Workbook

Sheet How to use this template.
A1: How to use this template.
A3: Before you start making any changes to this spreadsheet for your company's specific data, you should look at the template as it is and UNDERSTAND how it works and why things are done the way they are.
A8: There are several notes in the spreadsheet, you should read these ALL. They are designed to help you understand how/why things are linked the way they are. Some contain instructions for you to follow.
A13: Any yellow box you should input something. The orange boxes are calculated. The orange cells are not locked. This is because this template is designed for the most common businesses we have seen in the competition. Specific companies may have to do something other than what has been designed in the template. But make sure that you are certain you want to make a change before you do.
A20: The template was designed to handle up to three different revenue streams. If you have more than this, you will have to adapt the spreadsheet for additional income streams. If you have less than three revenue streams you can hide/delete these rows in the financial statements. If you decide to hide lines, just make sure you have entered a $0 on the assumptions tab.
A26: The expenses given on the Income Statement Assumptions tab are very common expenses. You can change the names of them if you want on the Assumptions tab. The expenses on the Assumptions tab are linked directly to the Income Statement. So if you change them on the assumptions page it will automatically correct it on the financial statements. Again if you do not have all of the expenses, you can hide/delete them from the Income Statement. DO NOT DELETE THEM ON THE ASSUMPTIONS TAB. If you decide to hide lines, just make sure you have entered a $0 on the assumptions tab.
A35: The input numbers in this template are completely absurd numbers. Do not assume that they are correct. You should change pretty much every number in yellow.

Sheet Income Statement Assumptions
A1: Sales:
A2: Product 1 sale via web
B3: Year 1
B4: January | C4: February | D4: March | E4: April | F4: May | G4: June | H4: July | I4: August | J4: September | K4: October | L4: November | M4: December | N4: Total
A5: Price per Unit | B5: 20 | C5: 20 | D5: 20 | E5: 20 | F5: 20 | G5: 20 | H5: 20 | I5: 20 | J5: 20 | K5: 20 | L5: 20 | M5: 20
A6: Units Sold | B6: 0 | C6: 0 | D6: 0 | E6: 0 | F6: 0 | G6: 0 | H6: 100 | I6: 150 | J6: 250 | K6: 300 | L6: 400 | M6: 500 | N6: =SUM(B6:M6) -> 1700
B8: Year 2
B9: January | C9: February | D9: March | E9: April | F9: May | G9: June | H9: July | I9: August | J9: September | K9: October | L9: November | M9: December | N9: Total
A10: Price per Unit | B10: 20 | C10: 20 | D10: 20 | E10: 20 | F10: 20 | G10: 20 | H10: 20 | I10: 20 | J10: 20 | K10: 20 | L10: 20 | M10: 20
A11: Units Sold | B11: =ROUND(M6*(1+D29),0) -> 563 | C11: =ROUND(B11*(1+$D$29),0) -> 633 | D11: =ROUND(C11*(1+$D$29),0) -> 712 | E11: =ROUND(D11*(1+$D$29),0) -> 801 | F11: =ROUND(E11*(1+$D$29),0) -> 901 | G11: =ROUND(F11*(1+$D$29),0) -> 1014 | H11: =ROUND(G11*(1+$D$29),0) -> 1141 | I11: =ROUND(H11*(1+$D$29),0) -> 1284 | J11: =ROUND(I11*(1+$D$29),0) -> 1445 | ... M11: =ROUND(L11*(1+$D$29),0) -> 2058 | N11: =SUM(B11:M11) -> 14007
B13: Year 3
D14: Quarter 1 | G14: Quarter 2 | J14: Quarter 3 | M14: Quarter 4 | N14: Total
A15: Price per Unit | D15: 22 | G15: 22 | J15: 22 | M15: 22
A16: Units Sold | D16: =ROUND((K11+L11+M11)*(1+D30),0) -> 6891 | G16: =ROUND(D16*(1+D30),0) -> 8614 | J16: =ROUND(G16*(1+D30),0) -> 10768 | M16: =ROUND(J16*(1+D30),0) -> 13460 | N16: =SUM(B16:M16) -> 39733
B18: Year 4
D19: Quarter 1 | G19: Quarter 2 | J19: Quarter 3 | M19: Quarter 4 | N19: Total
A20: Price per Unit | D20: 24 | G20: 24 | J20: 24 | M20: 24
A21: Units Sold | D21: =ROUND((M16)*(1+D31),0) -> 15479 | G21: =ROUND(D21*(1+D31),0) -> 17801 | J21: =ROUND(G21*(1+D31),0) -> 20471 | M21: =ROUND(J21*(1+D31),0) -> 23542 | N21: =SUM(B21:M21) -> 77293
B23: Year 5
N24: Total
A25: Price per Unit | M25: 25
A26: Units Sold | N26: =ROUND(N21*(1+D32),0) -> 100481
B28: Annual Rate | D28: Periodic Rate
A29: Year 2 Percentage Sales Growth | B29: 1.5 | D29: =B29/12 -> 0.125
A30: Year 3 Percentage Sales Growth | B30: 1 | D30: =B30/4 -> 0.25
A31: Year 4 Percentage Sales Growth | B31: 0.6 | D31: =B31/4 -> 0.15
A32: Year 5 Percentage Sales Growth | B32: 0.3 | D32: =B32 -> 0.3
A34: Product 2 Sale via Retailer
B35: Year 1
B36: January | C36: February | D36: March | E36: April | F36: May | G36: June | H36: July | I36: August | J36: September | K36: October | L36: November | M36: December | N36: Total
A37: Price per Unit | B37: 10 | C37: 10 | D37: 10 | E37: 10 | F37: 10 | G37: 10 | H37: 10 | I37: 10 | J37: 10 | K37: 10 | L37: 10 | M37: 10
A38: Units Sold | B38: 0 | C38: 0 | D38: 0 | E38: 0 | F38: 0 | G38: 0 | H38: 2000 | I38: 2000 | J38: 2500 | K38: 3000 | L38: 3000 | M38: 3500 | N38: =SUM(B38:M38) -> 16000
B40: Year 2
B41: January | C41: February | D41: March | E41: April | F41: May | G41: June | H41: July | I41: August | J41: September | K41: October | L41: November | M41: December | N41: Total
A42: Price per Unit | B42: 10 | C42: 10 | D42: 10 | E42: 10 | F42: 10 | G42: 10 | H42: 10 | I42: 10 | J42: 10 | K42: 10 | L42: 10 | M42: 10
A43: Units Sold | B43: =ROUND(M38*(1+D61),0) -> 3938 | C43: =ROUND(B43*(1+$D$29),0) -> 4430 | D43: =ROUND(C43*(1+$D$29),0) -> 4984 | E43: =ROUND(D43*(1+$D$29),0) -> 5607 | F43: =ROUND(E43*(1+$D$29),0) -> 6308 | G43: =ROUND(F43*(1+$D$29),0) -> 7097 | H43: =ROUND(G43*(1+$D$29),0) -> 7984 | I43: =ROUND(H43*(1+$D$29),0) -> 8982 | J43: =ROUND(I43*(1+$D$29),0) -> 10105 | ... M43: =ROUND(L43*(1+$D$29),0) -> 14388 | N43: =SUM(B43:M43) -> 97980
B45: Year 3
D46: Quarter 1 | G46: Quarter 2 | J46: Quarter 3 | M46: Quarter 4 | N46: Total
A47: Price per Unit | D47: 11 | G47: 11 | J47: 11 | M47: 11
A48: Units Sold | D48: =ROUND((K43+L43+M43)*(1+D62),0) -> 48181 | G48: =ROUND(D48*(1+D62),0) -> 60226 | J48: =ROUND(G48*(1+D62),0) -> 75283 | M48: =ROUND(J48*(1+D62),0) -> 94104 | N48: =SUM(B48:M48) -> 277794
...

Sheet Balance Sheet Assumptions
A1: Assets:
A3: Minimum Cash On Hand | B3: 100000 | C3: 3X your monthly burn rate
A5: Accounts Receivable as a percentage of sales | B5: 0.5
A7: Inventory as a percentage of COGS | B7: 0.4
A9: Fixed Assets - See Fixed Asset Tab
A12: Liabilities:
A14: Accounts Payable as a percentage of COGS | B14: 0.6
A17: Owners' Equity:
A19: Founders' Contribution | B19: 100000 | C19: $20,000 per founder
A20: Angel Investor's Contribution | B20: 675000 | C20: We solve for this later.
A22: Dividends Paid | B22: 0

Sheet Fixed Asset Assumptions
A1: Note: Do not think that just because you intend to work out of your parents garage/basement that you will not have fixed assets. If you have a sales force, don't assume that they are going to be using their own office equipment either. Also as your company grows you need to add more office furniture and equipment. If you are making a million dollars in sales you need more than what you started with.
A7: Tangible Asstes: Original Purchases Only
B8: Year 1 | C8: Year 2 | D8: Year 3 | E8: Year 4 | F8: Year 5
A9: Office:
A10: Computers | B10: 10000 | C10: 0 | D10: 0 | E10: 10000 | F10: 0
A11: Phones | B11: 4000 | C11: 0 | D11: 4000 | E11: 0 | F11: 4000
A12: Other Office Equipment | B12: 10000 | C12: 500 | D12: 500 | E12: 4000 | F12: 500
A14: Production:
A15: Machinery | B15: 0 | C15: 0 | D15: 0 | E15: 0 | F15: 0
A16: Transportation - Vehicle | B16: 10000 | C16: 0 | D16: 0 | E16: 0 | F16: 0
A17: Other Production Equipment | B17: 0 | C17: 0 | D17: 0 | E17: 0 | F17: 0
A19: Sales:
A20: Trade Booth for shows | B20: 15000 | C20: 2000 | D20: 0 | E20: 2000 | F20: 0
A21: Other Sales Equipment | B21: 0 | C21: 0 | D21: 0 | E21: 0 | F21: 0
A23: Total Additions to Fixed Assets | B23: =SUM(B10:B22) -> 49000 | C23: =SUM(C10:C22) -> 2500 | D23: =SUM(D10:D22) -> 4500 | E23: =SUM(E10:E22) -> 16000 | F23: =SUM(F10:F22) -> 4500
A25: Total Fixed Assets | B25: =B23 -> 49000 | C25: =C23+B25 -> 51500 | D25: =D23+C25 -> 56000 | E25: =E23+D25 -> 72000 | F25: =F23+E25 -> 76500
A27: Useful Life | B27: 5 | C27: 5 | D27: 5 | E27: =D27 -> 5 | F27: =E27 -> 5
A29: Annual Depreciation Expense | B29: =B25/B27 -> 9800 | C29: =C25/C27 -> 10300 | D29: =D25/D27 -> 11200 | E29: =E25/E27 -> 14400 | F29: =F25/F27 -> 15300
A31: Periodic Depreciation Expense | B31: =ROUND(B29/12,0) -> 817 | C31: =ROUND(C29/12,0) -> 858 | D31: =ROUND(D29/4,0) -> 2800 | E31: =ROUND(E29/4,0) -> 3600 | F31: =ROUND(F29,0) -> 15300
A35: Intangible Asstes: Original Purchases Only
B36: Year 1 | C36: Year 2 | D36: Year 3 | E36: Year 4 | F36: Year 5
A37: Patents | B37: 20000 | C37: 0 | D37: 0 | E37: 0 | F37: 0
A38: Trademarks | C38: 0 | D38: 0 | E38: 0 | F38: 0
A39: Other Intangible Assest | B39: 0 | C39: 0 | D39: 0 | E39: 0 | F39: 0
A41: Total Additions to Intangible Assets | B41: =SUM(B37:B40) -> 20000 | C41: =SUM(C37:C40) -> 0 | D41: =SUM(D37:D40) -> 0 | E41: =SUM(E37:E40) -> 0 | F41: =SUM(F37:F40) -> 0
A43: Total Fixed Assets | B43: =B41 -> 20000 | C43: =C41+B43 -> 20000 | D43: =D41+C43 -> 20000 | E43: =E41+D43 -> 20000 | F43: =F41+E43 -> 20000
A45: Useful Life | B45: 20 | C45: 20 | D45: 20 | E45: 20 | F45: =E45 -> 20
A47: Annual Depreciation Expense | B47: =B43/B45 -> 1000 | C47: =C43/C45 -> 1000 | D47: =D43/D45 -> 1000 | E47: =E43/E45 -> 1000 | F47: =F43/F45 -> 1000
A49: Periodic Depreciation Expense | B49: =ROUND(B47/12,0) -> 83 | C49: =ROUND(C47/12,0) -> 83 | D49: =ROUND(D47/4,0) -> 250 | E49: =ROUND(E47/4,0) -> 250 | F49: =ROUND(F47,0) -> 1000

Sheet Income Statement
B1: Company Name | O1: =B1 -> Company Name | AB1: =O1 -> Company Name
B2: Income Statement | O2: Income Statement | AB2: Income Statement
B4: Year 1 | O4: Year 2 | AB4: Year 3 | AG4: Year 4 | AL4: Year 5
A5: Revenue | B5: January | C5: February | D5: March | E5: April | F5: May | G5: June | H5: July | I5: August | J5: September | K5: October | L5: November | M5: December | N5: Total | O5: January | P5: February | Q5: March | R5: April | S5: May | T5: June | U5: July | V5: August | W5: September | X5: October | Y5: November | Z5: December | AA5: Total | AB5: Quarter 1 | AC5: Quarter 2 | AD5: Quarter 3 | AE5: Quarter 4 | AF5: Total | AG5: Quarter 1 | AH5: Quarter 2 | AI5: Quarter 3 | AJ5: Quarter 4 | AK5: Total | AL5: Total
A6: Product 1 | B6: ='Income Statement Assumptions'!B5*'Income Statement Assumptions'!B6 -> 0 | C6: ='Income Statement Assumptions'!C5*'Income Statement Assumptions'!C6 -> 0 | D6: ='Income Statement Assumptions'!D5*'Income Statement Assumptions'!D6 -> 0 | E6: ='Income Statement Assumptions'!E5*'Income Statement Assumptions'!E6 -> 0 | F6: ='Income Statement Assumptions'!F5*'Income Statement Assumptions'!F6 -> 0 | G6: ='Income Statement Assumptions'!G5*'Income Statement Assumptions'!G6 -> 0 | H6: ='Income Statement Assumptions'!H5*'Income Statement Assumptions'!H6 -> 2000 | I6: ='Income Statement Assumptions'!I5*'Income Statement Assumptions'!I6 -> 3000 | ... M6: ='Income Statement Assumptions'!M5*'Income Statement Assumptions'!M6 -> 10000 | N6: =SUM(B6:M6) -> 34000 | O6: ='Income Statement Assumptions'!B11*'Income Statement Assumptions'!B10 -> 11260 | P6: ='Income Statement Assumptions'!C11*'Income Statement Assumptions'!C10 -> 12660 | Q6: ='Income Statement Assumptions'!D11*'Income Statement Assumptions'!D10 -> 14240 | R6: ='Income Statement Assumptions'!E11*'Income Statement Assumptions'!E10 -> 16020 | S6: ='Income Statement Assumptions'!F11*'Income Statement Assumptions'!F10 -> 18020 | T6: ='Income Statement Assumptions'!G11*'Income Statement Assumptions'!G10 -> 20280 | U6: ='Income Statement Assumptions'!H11*'Income Statement Assumptions'!H10 -> 22820 | V6: ='Income Statement Assumptions'!I11*'Income Statement Assumptions'!I10 -> 25680 | ... Z6: ='Income Statement Assumptions'!M11*'Income Statement Assumptions'!M10 -> 41160 | AA6: =SUM(O6:Z6) -> 280140 | AB6: ='Income Statement Assumptions'!D15*'Income Statement Assumptions'!D16 -> 151602 | AC6: ='Income Statement Assumptions'!G15*'Income Statement Assumptions'!G16 -> 189508 | AD6: ='Income Statement Assumptions'!J15*'Income Statement Assumptions'!J16 -> 236896 | AE6: ='Income Statement Assumptions'!M15*'Income Statement Assumptions'!M16 -> 296120 | AF6: =SUM(AB6:AE6) -> 874126 | AG6: ='Income Statement Assumptions'!D20*'Income Statement Assumptions'!D21 -> 371496 | AH6: ='Income Statement Assumptions'!G20*'Income Statement Assumptions'!G21 -> 427224 | AI6: ='Income Statement Assumptions'!J20*'Income Statement Assumptions'!J21 -> 491304 | AJ6: ='Income Statement Assumptions'!M20*'Income Statement Assumptions'!M21 -> 565008 | AK6: =SUM(AG6:AJ6) -> 1855032 | AL6: ='Income Statement Assumptions'!M25*'Income Statement Assumptions'!N26 -> 2512025
A7: Product 2 | B7: ='Income Statement Assumptions'!B37*'Income Statement Assumptions'!B38 -> 0 | C7: ='Income Statement Assumptions'!C37*'Income Statement Assumptions'!C38 -> 0 | D7: ='Income Statement Assumptions'!D37*'Income Statement Assumptions'!D38 -> 0 | E7: ='Income Statement Assumptions'!E37*'Income Statement Assumptions'!E38 -> 0 | F7: ='Income Statement Assumptions'!F37*'Income Statement Assumptions'!F38 -> 0 | G7: ='Income Statement Assumptions'!G37*'Income Statement Assumptions'!G38 -> 0 | H7: ='Income Statement Assumptions'!H37*'Income Statement Assumptions'!H38 -> 20000 | I7: ='Income Statement Assumptions'!I37*'Income Statement Assumptions'!I38 -> 20000 | ... M7: ='Income Statement Assumptions'!M37*'Income Statement Assumptions'!M38 -> 35000 | N7: =SUM(B7:M7) -> 160000 | O7: ='Income Statement Assumptions'!B43*'Income Statement Assumptions'!B42 -> 39380 | P7: ='Income Statement Assumptions'!C43*'Income Statement Assumptions'!C42 -> 44300 | Q7: ='Income Statement Assumptions'!D43*'Income Statement Assumptions'!D42 -> 49840 | R7: ='Income Statement Assumptions'!E43*'Income Statement Assumptions'!E42 -> 56070 | S7: ='Income Statement Assumptions'!F43*'Income Statement Assumptions'!F42 -> 63080 | T7: ='Income Statement Assumptions'!G43*'Income Statement Assumptions'!G42 -> 70970 | U7: ='Income Statement Assumptions'!H43*'Income Statement Assumptions'!H42 -> 79840 | V7: ='Income Statement Assumptions'!I43*'Income Statement Assumptions'!I42 -> 89820 | ... Z7: ='Income Statement Assumptions'!M43*'Income Statement Assumptions'!M42 -> 143880 | AA7: =SUM(O7:Z7) -> 979800 | AB7: ='Income Statement Assumptions'!D47*'Income Statement Assumptions'!D48 -> 529991 | AC7: ='Income Statement Assumptions'!G47*'Income Statement Assumptions'!G48 -> 662486 | AD7: ='Income Statement Assumptions'!J47*'Income Statement Assumptions'!J48 -> 828113 | AE7: ='Income Statement Assumptions'!M47*'Income Statement Assumptions'!M48 -> 1035144 | AF7: =SUM(AB7:AE7) -> 3055734 | AG7: ='Income Statement Assumptions'!D52*'Income Statement Assumptions'!D53 -> 1298640 | AH7: ='Income Statement Assumptions'!G52*'Income Statement Assumptions'!G53 -> 1493436 | AI7: ='Income Statement Assumptions'!J52*'Income Statement Assumptions'!J53 -> 1717452 | AJ7: ='Income Statement Assumptions'!M52*'Income Statement Assumptions'!M53 -> 1975068 | AK7: =SUM(AG7:AJ7) -> 6484596 | AL7: ='Income Statement Assumptions'!M57*'Income Statement Assumptions'!N58 -> 8781225
A8: Product 3 | B8: ='Income Statement Assumptions'!B69*'Income Statement Assumptions'!B70 -> 0 | C8: ='Income Statement Assumptions'!C69*'Income Statement Assumptions'!C70 -> 0 | D8: ='Income Statement Assumptions'!D69*'Income Statement Assumptions'!D70 -> 0 | E8: ='Income Statement Assumptions'!E69*'Income Statement Assumptions'!E70 -> 0 | F8: ='Income Statement Assumptions'!F69*'Income Statement Assumptions'!F70 -> 0 | G8: ='Income Statement Assumptions'!G69*'Income Statement Assumptions'!G70 -> 0 | H8: ='Income Statement Assumptions'!H69*'Income Statement Assumptions'!H70 -> 2100 | I8: ='Income Statement Assumptions'!I69*'Income Statement Assumptions'!I70 -> 2150 | ... M8: ='Income Statement Assumptions'!M69*'Income Statement Assumptions'!M70 -> 4000 | N8: =SUM(B8:M8) -> 17950 | O8: ='Income Statement Assumptions'!B75*'Income Statement Assumptions'!B74 -> 4500 | P8: ='Income Statement Assumptions'!C75*'Income Statement Assumptions'!C74 -> 5062 | Q8: ='Income Statement Assumptions'!D75*'Income Statement Assumptions'!D74 -> 5694 | R8: ='Income Statement Assumptions'!E75*'Income Statement Assumptions'!E74 -> 6406 | S8: ='Income Statement Assumptions'!F75*'Income Statement Assumptions'!F74 -> 7206 | T8: ='Income Statement Assumptions'!G75*'Income Statement Assumptions'!G74 -> 8106 | U8: ='Income Statement Assumptions'!H75*'Income Statement Assumptions'!H74 -> 9120 | V8: ='Income Statement Assumptions'!I75*'Income Statement Assumptions'!I74 -> 10260 | ... Z8: ='Income Statement Assumptions'!M75*'Income Statement Assumptions'!M74 -> 16434 | AA8: =SUM(O8:Z8) -> 111922 | AB8: ='Income Statement Assumptions'!D79*'Income Statement Assumptions'!D80 -> 55032 | AC8: ='Income Statement Assumptions'!G79*'Income Statement Assumptions'!G80 -> 68790 | AD8: ='Income Statement Assumptions'!J79*'Income Statement Assumptions'!J80 -> 85988 | AE8: ='Income Statement Assumptions'!M79*'Income Statement Assumptions'!M80 -> 107486 | AF8: =SUM(AB8:AE8) -> 317296 | AG8: ='Income Statement Assumptions'!D84*'Income Statement Assumptions'!D85 -> 123608 | AH8: ='Income Statement Assumptions'!G84*'Income Statement Assumptions'!G85 -> 142150 | AI8: ='Income Statement Assumptions'!J84*'Income Statement Assumptions'!J85 -> 163472 | AJ8: ='Income Statement Assumptions'!M84*'Income Statement Assumptions'!M85 -> 187992 | AK8: =SUM(AG8:AJ8) -> 617222 | AL8: ='Income Statement Assumptions'!M89*'Income Statement Assumptions'!N90 -> 802388
A10: Total Revenue | B10: =SUM(B6:B9) -> 0 | C10: =SUM(C6:C9) -> 0 | D10: =SUM(D6:D9) -> 0 | E10: =SUM(E6:E9) -> 0 | F10: =SUM(F6:F9) -> 0 | G10: =SUM(G6:G9) -> 0 | H10: =SUM(H6:H9) -> 24100 | I10: =SUM(I6:I9) -> 25150 | ... M10: =SUM(M6:M9) -> 49000 | N10: =SUM(N6:N8) -> 211950 | O10: =SUM(O6:O9) -> 55140 | P10: =SUM(P6:P9) -> 62022 | Q10: =SUM(Q6:Q9) -> 69774 | R10: =SUM(R6:R9) -> 78496 | S10: =SUM(S6:S9) -> 88306 | T10: =SUM(T6:T9) -> 99356 | U10: =SUM(U6:U9) -> 111780 | V10: =SUM(V6:V9) -> 125760 | ... AL10: =SUM(AL6:AL9) -> 12095638
A12: Cost of Goods Sold
A13: =A6 -> Product 1
A14: ='Income Statement Assumptions'!A101 -> outsourced product | B14: ='Income Statement Assumptions'!$B$101*'Income Statement Assumptions'!B6 -> 0 | C14: ='Income Statement Assumptions'!$B$101*'Income Statement Assumptions'!C6 -> 0 | D14: ='Income Statement Assumptions'!$B$101*'Income Statement Assumptions'!D6 -> 0 | E14: ='Income Statement Assumptions'!$B$101*'Income Statement Assumptions'!E6 -> 0 | F14: ='Income Statement Assumptions'!$B$101*'Income Statement Assumptions'!F6 -> 0 | G14: ='Income Statement Assumptions'!$B$101*'Income Statement Assumptions'!G6 -> 0 | H14: ='Income Statement Assumptions'!$B$101*'Income Statement Assumptions'!H6 -> 525 | I14: ='Income Statement Assumptions'!$B$101*'Income Statement Assumptions'!I6 -> 787.5 | ... M14: ='Income Statement Assumptions'!$B$101*'Income Statement Assumptions'!M6 -> 2625 | N14: =SUM(B14:M14) -> 8925 | O14: =ROUND(('Income Statement Assumptions'!B$11*('Income Statement Assumptions'!$B101*(1+'Income Statement Assumptions'!$F$101))),0) -> 2961 | P14: =ROUND(('Income Statement Assumptions'!C$11*('Income Statement Assumptions'!$B101*(1+'Income Statement Assumptions'!$F$101))),0) -> 3329 | Q14: =ROUND(('Income Statement Assumptions'!D$11*('Income Statement Assumptions'!$B101*(1+'Income Statement Assumptions'!$F$101))),0) -> 3744 | R14: =ROUND(('Income Statement Assumptions'!E$11*('Income Statement Assumptions'!$B101*(1+'Income Statement Assumptions'!$F$101))),0) -> 4212 | S14: =ROUND(('Income Statement Assumptions'!F$11*('Income Statement Assumptions'!$B101*(1+'Income Statement Assumptions'!$F$101))),0) -> 4738 | T14: =ROUND(('Income Statement Assumptions'!G$11*('Income Statement Assumptions'!$B101*(1+'Income Statement Assumptions'!$F$101))),0) -> 5332 | U14: =ROUND(('Income Statement Assumptions'!H$11*('Income Statement Assumptions'!$B101*(1+'Income Statement Assumptions'!$F$101))),0) -> 6000 | V14: =ROUND(('Income Statement Assumptions'!I$11*('Income Statement Assumptions'!$B101*(1+'Income Statement Assumptions'!$F$101))),0) -> 6752 | ... Z14: =ROUND(('Income Statement Assumptions'!M$11*('Income Statement Assumptions'!$B101*(1+'Income Statement Assumptions'!$F$101))),0) -> 10823 | AA14: =SUM(O14:Z14) -> 73659 | AB14: =ROUND(('Income Statement Assumptions'!$B101*(1+'Income Statement Assumptions'!$D101)*(1+'Income Statement Assumptions'!$G101))*'Income Statement Assumptions'!D$16,0) -> 37086 | AC14: =ROUND(('Income Statement Assumptions'!$B101*(1+'Income Statement Assumptions'!$D101)*(1+'Income Statement Assumptions'!$G101))*'Income Statement Assumptions'!G$16,0) -> 46359 | AD14: =ROUND(('Income Statement Assumptions'!$B101*(1+'Income Statement Assumptions'!$D101)*(1+'Income Statement Assumptions'!$G101))*'Income Statement Assumptions'!J$16,0) -> 57951 | AE14: =ROUND(('Income Statement Assumptions'!$B101*(1+'Income Statement Assumptions'!$D101)*(1+'Income Statement Assumptions'!$G101))*'Income Statement Assumptions'!M$16,0) -> 72439 | AF14: =SUM(AB14:AE14) -> 213835 | AG14: =ROUND(('Income Statement Assumptions'!$B101*(1+'Income Statement Assumptions'!$D101)*(1+'Income Statement Assumptions'!$D101)*(1+'Income Statement Assumptions'!$H101)*'Income Statement Assumptions'!D$21),0) -> 84971 | AH14: =ROUND(('Income Statement Assumptions'!$B101*(1+'Income Statement Assumptions'!$D101)*(1+'Income Statement Assumptions'!$D101)*(1+'Income Statement Assumptions'!$H101)*'Income Statement Assumptions'!G$21),0) -> 97717 | AI14: =ROUND(('Income Statement Assumptions'!$B101*(1+'Income Statement Assumptions'!$D101)*(1+'Income Statement Assumptions'!$D101)*(1+'Income Statement Assumptions'!$H101)*'Income Statement Assumptions'!J$21),0) -> 112374 | AJ14: =ROUND(('Income Statement Assumptions'!$B101*(1+'Income Statement Assumptions'!$D101)*(1+'Income Statement Assumptions'!$D101)*(1+'Income Statement Assumptions'!$H101)*'Income Statement Assumptions'!M$21),0) -> 129232 | AK14: =SUM(AG14:AJ14) -> 424294 | AL14: =ROUND(('Income Statement Assumptions'!$B101*(1+'Income Statement Assumptions'!$D101)*(1+'Income Statement Assumptions'!$D101)*(1+'Income Statement Assumptions'!D101))*(1+'Income Statement Assumptions'!I101)*'Income Statement Assumptions'!N$26,0) -> 571010
A15: ='Income Statement Assumptions'!A102 -> 3PL | B15: ='Income Statement Assumptions'!$B102*'Income Statement Assumptions'!B6 -> 0 | C15: ='Income Statement Assumptions'!$B$102*'Income Statement Assumptions'!C6 -> 0 | D15: ='Income Statement Assumptions'!$B$102*'Income Statement Assumptions'!D6 -> 0 | E15: ='Income Statement Assumptions'!$B$102*'Income Statement Assumptions'!E6 -> 0 | F15: ='Income Statement Assumptions'!$B$102*'Income Statement Assumptions'!F6 -> 0 | G15: ='Income Statement Assumptions'!$B$102*'Income Statement Assumptions'!G6 -> 0 | H15: ='Income Statement Assumptions'!$B$102*'Income Statement Assumptions'!H6 -> 75 | I15: ='Income Statement Assumptions'!$B$102*'Income Statement Assumptions'!I6 -> 112.5 | J15: ='Income Statement Assumptions'!$B$102*'Income Statement Assumptions'!J6 -> 187.5 | ... M15: ='Income Statement Assumptions'!$B$102*'Income Statement Assumptions'!M6 -> 375 | N15: =SUM(B15:M15) -> 1275 | O15: =ROUND(('Income Statement Assumptions'!B$11*('Income Statement Assumptions'!$B102*(1+'Income Statement Assumptions'!$F$101))),0) -> 423 | P15: =ROUND(('Income Statement Assumptions'!C$11*('Income Statement Assumptions'!$B102*(1+'Income Statement Assumptions'!$F$101))),0) -> 476 | Q15: =ROUND(('Income Statement Assumptions'!D$11*('Income Statement Assumptions'!$B102*(1+'Income Statement Assumptions'!$F$101))),0) -> 535 | R15: =ROUND(('Income Statement Assumptions'!E$11*('Income Statement Assumptions'!$B102*(1+'Income Statement Assumptions'!$F$101))),0) -> 602 | S15: =ROUND(('Income Statement Assumptions'!F$11*('Income Statement Assumptions'!$B102*(1+'Income Statement Assumptions'!$F$101))),0) -> 677 | T15: =ROUND(('Income Statement Assumptions'!G$11*('Income Statement Assumptions'!$B102*(1+'Income Statement Assumptions'!$F$101))),0) -> 762 | U15: =ROUND(('Income Statement Assumptions'!H$11*('Income Statement Assumptions'!$B102*(1+'Income Statement Assumptions'!$F$101))),0) -> 857 | V15: =ROUND(('Income Statement Assumptions'!I$11*('Income Statement Assumptions'!$B102*(1+'Income Statement Assumptions'!$F$101))),0) -> 965 | ... Z15: =ROUND(('Income Statement Assumptions'!M$11*('Income Statement Assumptions'!$B102*(1+'Income Statement Assumptions'!$F$101))),0) -> 1546 | AA15: =SUM(O15:Z15) -> 10525 | AB15: =ROUND(('Income Statement Assumptions'!$B102*(1+'Income Statement Assumptions'!$D102)*(1+'Income Statement Assumptions'!$G102))*'Income Statement Assumptions'!D$16,0) -> 5298 | AC15: =ROUND(('Income Statement Assumptions'!$B102*(1+'Income Statement Assumptions'!$D102)*(1+'Income Statement Assumptions'!$G102))*'Income Statement Assumptions'!G$16,0) -> 6623 | AD15: =ROUND(('Income Statement Assumptions'!$B102*(1+'Income Statement Assumptions'!$D102)*(1+'Income Statement Assumptions'!$G102))*'Income Statement Assumptions'!J$16,0) -> 8279 | AE15: =ROUND(('Income Statement Assumptions'!$B102*(1+'Income Statement Assumptions'!$D102)*(1+'Income Statement Assumptions'!$G102))*'Income Statement Assumptions'!M$16,0) -> 10348 | AF15: =SUM(AB15:AE15) -> 30548 | AG15: =ROUND(('Income Statement Assumptions'!$B102*(1+'Income Statement Assumptions'!$D102)*(1+'Income Statement Assumptions'!$D102)*(1+'Income Statement Assumptions'!$H102)*'Income Statement Assumptions'!D$21),0) -> 12139 | AH15: =ROUND(('Income Statement Assumptions'!$B102*(1+'Income Statement Assumptions'!$D102)*(1+'Income Statement Assumptions'!$D102)*(1+'Income Statement Assumptions'!$H102)*'Income Statement Assumptions'!G$21),0) -> 13960 | AI15: =ROUND(('Income Statement Assumptions'!$B102*(1+'Income Statement Assumptions'!$D102)*(1+'Income Statement Assumptions'!$D102)*(1+'Income Statement Assumptions'!$H102)*'Income Statement Assumptions'!J$21),0) -> 16053 | AJ15: =ROUND(('Income Statement Assumptions'!$B102*(1+'Income Statement Assumptions'!$D102)*(1+'Income Statement Assumptions'!$D102)*(1+'Income Statement Assumptions'!$H102)*'Income Statement Assumptions'!M$21),0) -> 18462 | AK15: =SUM(AG15:AJ15) -> 60614 | AL15: =ROUND(('Income Statement Assumptions'!$B102*(1+'Income Statement Assumptions'!$D102)*(1+'Income Statement Assumptions'!$D102)*(1+'Income Statement Assumptions'!D102))*(1+'Income Statement Assumptions'!I102)*'Income Statement Assumptions'!N$26,0) -> 81573
A16: ='Income Statement Assumptions'!A103 -> CC fee | B16: ='Income Statement Assumptions'!$B103*'Income Statement Assumptions'!B6 -> 0 | C16: ='Income Statement Assumptions'!$B103*'Income Statement Assumptions'!C6 -> 0 | D16: ='Income Statement Assumptions'!$B103*'Income Statement Assumptions'!D6 -> 0 | E16: ='Income Statement Assumptions'!$B103*'Income Statement Assumptions'!E6 -> 0 | F16: ='Income Statement Assumptions'!$B103*'Income Statement Assumptions'!F6 -> 0 | G16: ='Income Statement Assumptions'!$B103*'Income Statement Assumptions'!G6 -> 0 | H16: ='Income Statement Assumptions'!$B103*'Income Statement Assumptions'!H6 -> 60 | I16: ='Income Statement Assumptions'!$B103*'Income Statement Assumptions'!I6 -> 90 | ... M16: ='Income Statement Assumptions'!$B103*'Income Statement Assumptions'!M6 -> 300 | N16: =SUM(B16:M16) -> 1020 | O16: =ROUND(('Income Statement Assumptions'!B$11*('Income Statement Assumptions'!$B103*(1+'Income Statement Assumptions'!$F$101))),0) -> 338 | P16: =ROUND(('Income Statement Assumptions'!C$11*('Income Statement Assumptions'!$B103*(1+'Income Statement Assumptions'!$F$101))),0) -> 380 | Q16: =ROUND(('Income Statement Assumptions'!D$11*('Income Statement Assumptions'!$B103*(1+'Income Statement Assumptions'!$F$101))),0) -> 428 | R16: =ROUND(('Income Statement Assumptions'!E$11*('Income Statement Assumptions'!$B103*(1+'Income Statement Assumptions'!$F$101))),0) -> 481 | S16: =ROUND(('Income Statement Assumptions'!F$11*('Income Statement Assumptions'!$B103*(1+'Income Statement Assumptions'!$F$101))),0) -> 542 | T16: =ROUND(('Income Statement Assumptions'!G$11*('Income Statement Assumptions'!$B103*(1+'Income Statement Assumptions'!$F$101))),0) -> 609 | U16: =ROUND(('Income Statement Assumptions'!H$11*('Income Statement Assumptions'!$B103*(1+'Income Statement Assumptions'!$F$101))),0) -> 686 | V16: =ROUND(('Income Statement Assumptions'!I$11*('Income Statement Assumptions'!$B103*(1+'Income Statement Assumptions'!$F$101))),0) -> 772 | ... Z16: =ROUND(('Income Statement Assumptions'!M$11*('Income Statement Assumptions'!$B103*(1+'Income Statement Assumptions'!$F$101))),0) -> 1237 | AA16: =SUM(O16:Z16) -> 8417 | AB16: =ROUND(('Income Statement Assumptions'!$B103*(1+'Income Statement Assumptions'!$D103)*(1+'Income Statement Assumptions'!$G103))*'Income Statement Assumptions'!D$16,0) -> 4238 | AC16: =ROUND(('Income Statement Assumptions'!$B103*(1+'Income Statement Assumptions'!$D103)*(1+'Income Statement Assumptions'!$G103))*'Income Statement Assumptions'!G$16,0) -> 5298 | AD16: =ROUND(('Income Statement Assumptions'!$B103*(1+'Income Statement Assumptions'!$D103)*(1+'Income Statement Assumptions'!$G103))*'Income Statement Assumptions'!J$16,0) -> 6623 | AE16: =ROUND(('Income Statement Assumptions'!$B103*(1+'Income Statement Assumptions'!$D103)*(1+'Income Statement Assumptions'!$G103))*'Income Statement Assumptions'!M$16,0) -> 8279 | AF16: =SUM(AB16:AE16) -> 24438 | AG16: =ROUND(('Income Statement Assumptions'!$B103*(1+'Income Statement Assumptions'!$D103)*(1+'Income Statement Assumptions'!$D103)*(1+'Income Statement Assumptions'!$H103)*'Income Statement Assumptions'!D$21),0) -> 9711 | AH16: =ROUND(('Income Statement Assumptions'!$B103*(1+'Income Statement Assumptions'!$D103)*(1+'Income Statement Assumptions'!$D103)*(1+'Income Statement Assumptions'!$H103)*'Income Statement Assumptions'!G$21),0) -> 11168 | AI16: =ROUND(('Income Statement Assumptions'!$B103*(1+'Income Statement Assumptions'!$D103)*(1+'Income Statement Assumptions'!$D103)*(1+'Income Statement Assumptions'!$H103)*'Income Statement Assumptions'!J$21),0) -> 12843 | AJ16: =ROUND(('Income Statement Assumptions'!$B103*(1+'Income Statement Assumptions'!$D103)*(1+'Income Statement Assumptions'!$D103)*(1+'Income Statement Assumptions'!$H103)*'Income Statement Assumptions'!M$21),0) -> 14769 | AK16: =SUM(AG16:AJ16) -> 48491 | AL16: =ROUND(('Income Statement Assumptions'!$B103*(1+'Income Statement Assumptions'!$D103)*(1+'Income Statement Assumptions'!$D103)*(1+'Income Statement Assumptions'!D103))*(1+'Income Statement Assumptions'!I103)*'Income Statement Assumptions'!N$26,0) -> 65258
A17: ='Income Statement Assumptions'!A104 -> warranty | B17: ='Income Statement Assumptions'!$B104*'Income Statement Assumptions'!B6 -> 0 | C17: ='Income Statement Assumptions'!$B104*'Income Statement Assumptions'!C6 -> 0 | D17: ='Income Statement Assumptions'!$B104*'Income Statement Assumptions'!D6 -> 0 | E17: ='Income Statement Assumptions'!$B104*'Income Statement Assumptions'!E6 -> 0 | F17: ='Income Statement Assumptions'!$B104*'Income Statement Assumptions'!F6 -> 0 | G17: ='Income Statement Assumptions'!$B104*'Income Statement Assumptions'!G6 -> 0 | H17: ='Income Statement Assumptions'!$B104*'Income Statement Assumptions'!H6 -> 15 | I17: ='Income Statement Assumptions'!$B104*'Income Statement Assumptions'!I6 -> 22.5 | ... M17: ='Income Statement Assumptions'!$B104*'Income Statement Assumptions'!M6 -> 75 | N17: =SUM(B17:M17) -> 255 | O17: =ROUND(('Income Statement Assumptions'!B$11*('Income Statement Assumptions'!$B104*(1+'Income Statement Assumptions'!$F$101))),0) -> 85 | P17: =ROUND(('Income Statement Assumptions'!C$11*('Income Statement Assumptions'!$B104*(1+'Income Statement Assumptions'!$F$101))),0) -> 95 | Q17: =ROUND(('Income Statement Assumptions'!D$11*('Income Statement Assumptions'!$B104*(1+'Income Statement Assumptions'!$F$101))),0) -> 107 | R17: =ROUND(('Income Statement Assumptions'!E$11*('Income Statement Assumptions'!$B104*(1+'Income Statement Assumptions'!$F$101))),0) -> 120 | S17: =ROUND(('Income Statement Assumptions'!F$11*('Income Statement Assumptions'!$B104*(1+'Income Statement Assumptions'!$F$101))),0) -> 135 | T17: =ROUND(('Income Statement Assumptions'!G$11*('Income Statement Assumptions'!$B104*(1+'Income Statement Assumptions'!$F$101))),0) -> 152 | U17: =ROUND(('Income Statement Assumptions'!H$11*('Income Statement Assumptions'!$B104*(1+'Income Statement Assumptions'!$F$101))),0) -> 171 | V17: =ROUND(('Income Statement Assumptions'!I$11*('Income Statement Assumptions'!$B104*(1+'Income Statement Assumptions'!$F$101))),0) -> 193 | ... Z17: =ROUND(('Income Statement Assumptions'!M$11*('Income Statement Assumptions'!$B104*(1+'Income Statement Assumptions'!$F$101))),0) -> 309 | AA17: =SUM(O17:Z17) -> 2103 | AB17: =ROUND(('Income Statement Assumptions'!$B104*(1+'Income Statement Assumptions'!$D104)*(1+'Income Statement Assumptions'!$G104))*'Income Statement Assumptions'!D$16,0) -> 1099 | AC17: =ROUND(('Income Statement Assumptions'!$B104*(1+'Income Statement Assumptions'!$D104)*(1+'Income Statement Assumptions'!$G104))*'Income Statement Assumptions'!G$16,0) -> 1374 | AD17: =ROUND(('Income Statement Assumptions'!$B104*(1+'Income Statement Assumptions'!$D104)*(1+'Income Statement Assumptions'!$G104))*'Income Statement Assumptions'!J$16,0) -> 1717 | AE17: =ROUND(('Income Statement Assumptions'!$B104*(1+'Income Statement Assumptions'!$D104)*(1+'Income Statement Assumptions'!$G104))*'Income Statement Assumptions'!M$16,0) -> 2146 | AF17: =SUM(AB17:AE17) -> 6336 | AG17: =ROUND(('Income Statement Assumptions'!$B104*(1+'Income Statement Assumptions'!$D104)*(1+'Income Statement Assumptions'!$D104)*(1+'Income Statement Assumptions'!$H104)*'Income Statement Assumptions'!D$21),0) -> 2592 | AH17: =ROUND(('Income Statement Assumptions'!$B104*(1+'Income Statement Assumptions'!$D104)*(1+'Income Statement Assumptions'!$D104)*(1+'Income Statement Assumptions'!$H104)*'Income Statement Assumptions'!G$21),0) -> 2981 | AI17: =ROUND(('Income Statement Assumptions'!$B104*(1+'Income Statement Assumptions'!$D104)*(1+'Income Statement Assumptions'!$D104)*(1+'Income Statement Assumptions'!$H104)*'Income Statement Assumptions'!J$21),0) -> 3428 | AJ17: =ROUND(('Income Statement Assumptions'!$B104*(1+'Income Statement Assumptions'!$D104)*(1+'Income Statement Assumptions'!$D104)*(1+'Income Statement Assumptions'!$H104)*'Income Statement Assumptions'!M$21),0) -> 3942 | AK17: =SUM(AG17:AJ17) -> 12943 | AL17: =ROUND(('Income Statement Assumptions'!$B104*(1+'Income Statement Assumptions'!$D104)*(1+'Income Statement Assumptions'!$D104)*(1+'Income Statement Assumptions'!D104))*(1+'Income Statement Assumptions'!I104)*'Income Statement Assumptions'!N$26,0) -> 18320
A19: =A7 -> Product 2
A20: ='Income Statement Assumptions'!A107 -> Outsourced product | B20: ='Income Statement Assumptions'!$B107*'Income Statement Assumptions'!B38 -> 0 | C20: ='Income Statement Assumptions'!$B107*'Income Statement Assumptions'!C38 -> 0 | D20: ='Income Statement Assumptions'!$B107*'Income Statement Assumptions'!D38 -> 0 | E20: ='Income Statement Assumptions'!$B107*'Income Statement Assumptions'!E38 -> 0 | F20: ='Income Statement Assumptions'!$B107*'Income Statement Assumptions'!F38 -> 0 | G20: ='Income Statement Assumptions'!$B107*'Income Statement Assumptions'!G38 -> 0 | H20: ='Income Statement Assumptions'!$B107*'Income Statement Assumptions'!H38 -> 10500 | I20: ='Income Statement Assumptions'!$B107*'Income Statement Assumptions'!I38 -> 10500 | ... M20: ='Income Statement Assumptions'!$B107*'Income Statement Assumptions'!M38 -> 18375 | N20: =SUM(B20:M20) -> 84000 | O20: =ROUND(('Income Statement Assumptions'!B$43*('Income Statement Assumptions'!$B107*(1+'Income Statement Assumptions'!$F$107))),0) -> 20709 | P20: =ROUND(('Income Statement Assumptions'!C$43*('Income Statement Assumptions'!$B107*(1+'Income Statement Assumptions'!$F$107))),0) -> 23296 | Q20: =ROUND(('Income Statement Assumptions'!D$43*('Income Statement Assumptions'!$B107*(1+'Income Statement Assumptions'!$F$107))),0) -> 26210 | R20: =ROUND(('Income Statement Assumptions'!E$43*('Income Statement Assumptions'!$B107*(1+'Income Statement Assumptions'!$F$107))),0) -> 29486 | S20: =ROUND(('Income Statement Assumptions'!F$43*('Income Statement Assumptions'!$B107*(1+'Income Statement Assumptions'!$F$107))),0) -> 33172 | T20: =ROUND(('Income Statement Assumptions'!G$43*('Income Statement Assumptions'!$B107*(1+'Income Statement Assumptions'!$F$107))),0) -> 37321 | U20: =ROUND(('Income Statement Assumptions'!H$43*('Income Statement Assumptions'!$B107*(1+'Income Statement Assumptions'!$F$107))),0) -> 41986 | V20: =ROUND(('Income Statement Assumptions'!I$43*('Income Statement Assumptions'!$B107*(1+'Income Statement Assumptions'!$F$107))),0) -> 47234 | ... Z20: =ROUND(('Income Statement Assumptions'!M$43*('Income Statement Assumptions'!$B107*(1+'Income Statement Assumptions'!$F$107))),0) -> 75663 | AA20: =SUM(O20:Z20) -> 515252 | AB20: =ROUND(('Income Statement Assumptions'!$B107*(1+'Income Statement Assumptions'!$D107)*(1+'Income Statement Assumptions'!$G107))*'Income Statement Assumptions'!D$48,0) -> 259299 | AC20: =ROUND(('Income Statement Assumptions'!$B107*(1+'Income Statement Assumptions'!$D107)*(1+'Income Statement Assumptions'!$G107))*'Income Statement Assumptions'!G$48,0) -> 324123 | AD20: =ROUND(('Income Statement Assumptions'!$B107*(1+'Income Statement Assumptions'!$D107)*(1+'Income Statement Assumptions'!$G107))*'Income Statement Assumptions'!J$48,0) -> 405156 | AE20: =ROUND(('Income Statement Assumptions'!$B107*(1+'Income Statement Assumptions'!$D107)*(1+'Income Statement Assumptions'!$G107))*'Income Statement Assumptions'!M$48,0) -> 506447 | AF20: =SUM(AB20:AE20) -> 1495025 | AG20: =ROUND(('Income Statement Assumptions'!$B107*(1+'Income Statement Assumptions'!$D107)*(1+'Income Statement Assumptions'!$D107)*(1+'Income Statement Assumptions'!$H107)*'Income Statement Assumptions'!D$53),0) -> 594064 | AH20: =ROUND(('Income Statement Assumptions'!$B107*(1+'Income Statement Assumptions'!$D107)*(1+'Income Statement Assumptions'!$D107)*(1+'Income Statement Assumptions'!$H107)*'Income Statement Assumptions'!G$53),0) -> 683174 | AI20: =ROUND(('Income Statement Assumptions'!$B107*(1+'Income Statement Assumptions'!$D107)*(1+'Income Statement Assumptions'!$D107)*(1+'Income Statement Assumptions'!$H107)*'Income Statement Assumptions'!J$53),0) -> 785650 | AJ20: =ROUND(('Income Statement Assumptions'!$B107*(1+'Income Statement Assumptions'!$D107)*(1+'Income Statement Assumptions'!$D107)*(1+'Income Statement Assumptions'!$H107)*'Income Statement Assumptions'!M$53),0) -> 903497 | AK20: =SUM(AG20:AJ20) -> 2966385 | AL20: =ROUND(('Income Statement Assumptions'!$B107*(1+'Income Statement Assumptions'!$D107)*(1+'Income Statement Assumptions'!$D107)*(1+'Income Statement Assumptions'!D107))*(1+'Income Statement Assumptions'!I107)*'Income Statement Assumptions'!N$58,0) -> 3992134
A21: ='Income Statement Assumptions'!A108 -> 3PL | B21: ='Income Statement Assumptions'!$B108*'Income Statement Assumptions'!B38 -> 0 | C21: ='Income Statement Assumptions'!$B108*'Income Statement Assumptions'!C38 -> 0 | D21: ='Income Statement Assumptions'!$B108*'Income Statement Assumptions'!D38 -> 0 | E21: ='Income Statement Assumptions'!$B108*'Income Statement Assumptions'!E38 -> 0 | F21: ='Income Statement Assumptions'!$B108*'Income Statement Assumptions'!F38 -> 0 | G21: ='Income Statement Assumptions'!$B108*'Income Statement Assumptions'!G38 -> 0 | H21: ='Income Statement Assumptions'!$B108*'Income Statement Assumptions'!H38 -> 1500 | I21: ='Income Statement Assumptions'!$B108*'Income Statement Assumptions'!I38 -> 1500 | ... M21: ='Income Statement Assumptions'!$B108*'Income Statement Assumptions'!M38 -> 2625 | N21: =SUM(B21:M21) -> 12000 | O21: =ROUND(('Income Statement Assumptions'!B$43*('Income Statement Assumptions'!$B108*(1+'Income Statement Assumptions'!$F$107))),0) -> 2958 | P21: =ROUND(('Income Statement Assumptions'!C$43*('Income Statement Assumptions'!$B108*(1+'Income Statement Assumptions'!$F$107))),0) -> 3328 | Q21: =ROUND(('Income Statement Assumptions'!D$43*('Income Statement Assumptions'!$B108*(1+'Income Statement Assumptions'!$F$107))),0) -> 3744 | R21: =ROUND(('Income Statement Assumptions'!E$43*('Income Statement Assumptions'!$B108*(1+'Income Statement Assumptions'!$F$107))),0) -> 4212 | S21: =ROUND(('Income Statement Assumptions'!F$43*('Income Statement Assumptions'!$B108*(1+'Income Statement Assumptions'!$F$107))),0) -> 4739 | T21: =ROUND(('Income Statement Assumptions'!G$43*('Income Statement Assumptions'!$B108*(1+'Income Statement Assumptions'!$F$107))),0) -> 5332 | U21: =ROUND(('Income Statement Assumptions'!H$43*('Income Statement Assumptions'!$B108*(1+'Income Statement Assumptions'!$F$107))),0) -> 5998 | V21: =ROUND(('Income Statement Assumptions'!I$43*('Income Statement Assumptions'!$B108*(1+'Income Statement Assumptions'!$F$107))),0) -> 6748 | ... Z21: =ROUND(('Income Statement Assumptions'!M$43*('Income Statement Assumptions'!$B108*(1+'Income Statement Assumptions'!$F$107))),0) -> 10809 | AA21: =SUM(O21:Z21) -> 73607 | AB21: =ROUND(('Income Statement Assumptions'!$B108*(1+'Income Statement Assumptions'!$D108)*(1+'Income Statement Assumptions'!$G108))*'Income Statement Assumptions'!D$48,0) -> 37043 | AC21: =ROUND(('Income Statement Assumptions'!$B108*(1+'Income Statement Assumptions'!$D108)*(1+'Income Statement Assumptions'!$G108))*'Income Statement Assumptions'!G$48,0) -> 46303 | AD21: =ROUND(('Income Statement Assumptions'!$B108*(1+'Income Statement Assumptions'!$D108)*(1+'Income Statement Assumptions'!$G108))*'Income Statement Assumptions'!J$48,0) -> 57879 | AE21: =ROUND(('Income Statement Assumptions'!$B108*(1+'Income Statement Assumptions'!$D108)*(1+'Income Statement Assumptions'!$G108))*'Income Statement Assumptions'!M$48,0) -> 72350 | AF21: =SUM(AB21:AE21) -> 213575 | AG21: =ROUND(('Income Statement Assumptions'!$B108*(1+'Income Statement Assumptions'!$D108)*(1+'Income Statement Assumptions'!$D108)*(1+'Income Statement Assumptions'!$H108)*'Income Statement Assumptions'!D$53),0) -> 84866 | AH21: =ROUND(('Income Statement Assumptions'!$B108*(1+'Income Statement Assumptions'!$D108)*(1+'Income Statement Assumptions'!$D108)*(1+'Income Statement Assumptions'!$H108)*'Income Statement Assumptions'!G$53),0) -> 97596 | AI21: =ROUND(('Income Statement Assumptions'!$B108*(1+'Income Statement Assumptions'!$D108)*(1+'Income Statement Assumptions'!$D108)*(1+'Income Statement Assumptions'!$H108)*'Income Statement Assumptions'!J$53),0) -> 112236 | AJ21: =ROUND(('Income Statement Assumptions'!$B108*(1+'Income Statement Assumptions'!$D108)*(1+'Income Statement Assumptions'!$D108)*(1+'Income Statement Assumptions'!$H108)*'Income Statement Assumptions'!M$53),0) -> 129071 | AK21: =SUM(AG21:AJ21) -> 423769 | AL21: =ROUND(('Income Statement Assumptions'!$B108*(1+'Income Statement Assumptions'!$D108)*(1+'Income Statement Assumptions'!$D108)*(1+'Income Statement Assumptions'!D108))*(1+'Income Statement Assumptions'!I108)*'Income Statement Assumptions'!N$58,0) -> 570305
A22: ='Income Statement Assumptions'!A109 -> CC fee | B22: ='Income Statement Assumptions'!$B109*'Income Statement Assumptions'!B38 -> 0 | C22: ='Income Statement Assumptions'!$B109*'Income Statement Assumptions'!C38 -> 0 | D22: ='Income Statement Assumptions'!$B109*'Income Statement Assumptions'!D38 -> 0 | E22: ='Income Statement Assumptions'!$B109*'Income Statement Assumptions'!E38 -> 0 | F22: ='Income Statement Assumptions'!$B109*'Income Statement Assumptions'!F38 -> 0 | G22: ='Income Statement Assumptions'!$B109*'Income Statement Assumptions'!G38 -> 0 | H22: ='Income Statement Assumptions'!$B109*'Income Statement Assumptions'!H38 -> 0 | I22: ='Income Statement Assumptions'!$B109*'Income Statement Assumptions'!I38 -> 0 | ... M22: ='Income Statement Assumptions'!$B109*'Income Statement Assumptions'!M38 -> 0 | N22: =SUM(B22:M22) -> 0 | O22: =ROUND(('Income Statement Assumptions'!B$43*('Income Statement Assumptions'!$B109*(1+'Income Statement Assumptions'!$F$107))),0) -> 0 | P22: =ROUND(('Income Statement Assumptions'!C$43*('Income Statement Assumptions'!$B109*(1+'Income Statement Assumptions'!$F$107))),0) -> 0 | Q22: =ROUND(('Income Statement Assumptions'!D$43*('Income Statement Assumptions'!$B109*(1+'Income Statement Assumptions'!$F$107))),0) -> 0 | R22: =ROUND(('Income Statement Assumptions'!E$43*('Income Statement Assumptions'!$B109*(1+'Income Statement Assumptions'!$F$107))),0) -> 0 | S22: =ROUND(('Income Statement Assumptions'!F$43*('Income Statement Assumptions'!$B109*(1+'Income Statement Assumptions'!$F$107))),0) -> 0 | T22: =ROUND(('Income Statement Assumptions'!G$43*('Income Statement Assumptions'!$B109*(1+'Income Statement Assumptions'!$F$107))),0) -> 0 | U22: =ROUND(('Income Statement Assumptions'!H$43*('Income Statement Assumptions'!$B109*(1+'Income Statement Assumptions'!$F$107))),0) -> 0 | V22: =ROUND(('Income Statement Assumptions'!I$43*('Income Statement Assumptions'!$B109*(1+'Income Statement Assumptions'!$F$107))),0) -> 0 | ... Z22: =ROUND(('Income Statement Assumptions'!M$43*('Income Statement Assumptions'!$B109*(1+'Income Statement Assumptions'!$F$107))),0) -> 0 | AA22: =SUM(O22:Z22) -> 0 | AB22: =ROUND(('Income Statement Assumptions'!$B109*(1+'Income Statement Assumptions'!$D109)*(1+'Income Statement Assumptions'!$G109))*'Income Statement Assumptions'!D$48,0) -> 0 | AC22: =ROUND(('Income Statement Assumptions'!$B109*(1+'Income Statement Assumptions'!$D109)*(1+'Income Statement Assumptions'!$G109))*'Income Statement Assumptions'!G$48,0) -> 0 | AD22: =ROUND(('Income Statement Assumptions'!$B109*(1+'Income Statement Assumptions'!$D109)*(1+'Income Statement Assumptions'!$G109))*'Income Statement Assumptions'!J$48,0) -> 0 | AE22: =ROUND(('Income Statement Assumptions'!$B109*(1+'Income Statement Assumptions'!$D109)*(1+'Income Statement Assumptions'!$G109))*'Income Statement Assumptions'!M$48,0) -> 0 | AF22: =SUM(AB22:AE22) -> 0 | AG22: =ROUND(('Income Statement Assumptions'!$B109*(1+'Income Statement Assumptions'!$D109)*(1+'Income Statement Assumptions'!$D109)*(1+'Income Statement Assumptions'!$H109)*'Income Statement Assumptions'!D$53),0) -> 0 | AH22: =ROUND(('Income Statement Assumptions'!$B109*(1+'Income Statement Assumptions'!$D109)*(1+'Income Statement Assumptions'!$D109)*(1+'Income Statement Assumptions'!$H109)*'Income Statement Assumptions'!G$53),0) -> 0 | AI22: =ROUND(('Income Statement Assumptions'!$B109*(1+'Income Statement Assumptions'!$D109)*(1+'Income Statement Assumptions'!$D109)*(1+'Income Statement Assumptions'!$H109)*'Income Statement Assumptions'!J$53),0) -> 0 | AJ22: =ROUND(('Income Statement Assumptions'!$B109*(1+'Income Statement Assumptions'!$D109)*(1+'Income Statement Assumptions'!$D109)*(1+'Income Statement Assumptions'!$H109)*'Income Statement Assumptions'!M$53),0) -> 0 | AK22: =SUM(AG22:AJ22) -> 0 | AL22: =ROUND(('Income Statement Assumptions'!$B109*(1+'Income Statement Assumptions'!$D109)*(1+'Income Statement Assumptions'!$D109)*(1+'Income Statement Assumptions'!D109))*(1+'Income Statement Assumptions'!I109)*'Income Statement Assumptions'!N$58,0) -> 0
A23: ='Income Statement Assumptions'!A110 -> warranty | B23: ='Income Statement Assumptions'!$B110*'Income Statement Assumptions'!B38 -> 0 | C23: ='Income Statement Assumptions'!$B110*'Income Statement Assumptions'!C38 -> 0 | D23: ='Income Statement Assumptions'!$B110*'Income Statement Assumptions'!D38 -> 0 | E23: ='Income Statement Assumptions'!$B110*'Income Statement Assumptions'!E38 -> 0 | F23: ='Income Statement Assumptions'!$B110*'Income Statement Assumptions'!F38 -> 0 | G23: ='Income Statement Assumptions'!$B110*'Income Statement Assumptions'!G38 -> 0 | H23: ='Income Statement Assumptions'!$B110*'Income Statement Assumptions'!H38 -> 300 | I23: ='Income Statement Assumptions'!$B110*'Income Statement Assumptions'!I38 -> 300 | ... M23: ='Income Statement Assumptions'!$B110*'Income Statement Assumptions'!M38 -> 525 | N23: =SUM(B23:M23) -> 2400 | O23: =ROUND(('Income Statement Assumptions'!B$43*('Income Statement Assumptions'!$B110*(1+'Income Statement Assumptions'!$F$107))),0) -> 592 | P23: =ROUND(('Income Statement Assumptions'!C$43*('Income Statement Assumptions'!$B110*(1+'Income Statement Assumptions'!$F$107))),0) -> 666 | Q23: =ROUND(('Income Statement Assumptions'!D$43*('Income Statement Assumptions'!$B110*(1+'Income Statement Assumptions'!$F$107))),0) -> 749 | R23: =ROUND(('Income Statement Assumptions'!E$43*('Income Statement Assumptions'!$B110*(1+'Income Statement Assumptions'!$F$107))),0) -> 842 | S23: =ROUND(('Income Statement Assumptions'!F$43*('Income Statement Assumptions'!$B110*(1+'Income Statement Assumptions'!$F$107))),0) -> 948 | T23: =ROUND(('Income Statement Assumptions'!G$43*('Income Statement Assumptions'!$B110*(1+'Income Statement Assumptions'!$F$107))),0) -> 1066 | U23: =ROUND(('Income Statement Assumptions'!H$43*('Income Statement Assumptions'!$B110*(1+'Income Statement Assumptions'!$F$107))),0) -> 1200 | V23: =ROUND(('Income Statement Assumptions'!I$43*('Income Statement Assumptions'!$B110*(1+'Income Statement Assumptions'!$F$107))),0) -> 1350 | ... Z23: =ROUND(('Income Statement Assumptions'!M$43*('Income Statement Assumptions'!$B110*(1+'Income Statement Assumptions'!$F$107))),0) -> 2162 | AA23: =SUM(O23:Z23) -> 14723 | AB23: =ROUND(('Income Statement Assumptions'!$B110*(1+'Income Statement Assumptions'!$D110)*(1+'Income Statement Assumptions'!$G110))*'Income Statement Assumptions'!D$48,0) -> 7683 | AC23: =ROUND(('Income Statement Assumptions'!$B110*(1+'Income Statement Assumptions'!$D110)*(1+'Income Statement Assumptions'!$G110))*'Income Statement Assumptions'!G$48,0) -> 9604 | AD23: =ROUND(('Income Statement Assumptions'!$B110*(1+'Income Statement Assumptions'!$D110)*(1+'Income Statement Assumptions'!$G110))*'Income Statement Assumptions'!J$48,0) -> 12005 | AE23: =ROUND(('Income Statement Assumptions'!$B110*(1+'Income Statement Assumptions'!$D110)*(1+'Income Statement Assumptions'!$G110))*'Income Statement Assumptions'!M$48,0) -> 15007 | AF23: =SUM(AB23:AE23) -> 44299 | AG23: =ROUND(('Income Statement Assumptions'!$B110*(1+'Income Statement Assumptions'!$D110)*(1+'Income Statement Assumptions'!$D110)*(1+'Income Statement Assumptions'!$H110)*'Income Statement Assumptions'!D$53),0) -> 18121 | AH23: =ROUND(('Income Statement Assumptions'!$B110*(1+'Income Statement Assumptions'!$D110)*(1+'Income Statement Assumptions'!$D110)*(1+'Income Statement Assumptions'!$H110)*'Income Statement Assumptions'!G$53),0) -> 20839 | AI23: =ROUND(('Income Statement Assumptions'!$B110*(1+'Income Statement Assumptions'!$D110)*(1+'Income Statement Assumptions'!$D110)*(1+'Income Statement Assumptions'!$H110)*'Income Statement Assumptions'!J$53),0) -> 23964 | AJ23: =ROUND(('Income Statement Assumptions'!$B110*(1+'Income Statement Assumptions'!$D110)*(1+'Income Statement Assumptions'!$D110)*(1+'Income Statement Assumptions'!$H110)*'Income Statement Assumptions'!M$53),0) -> 27559 | AK23: =SUM(AG23:AJ23) -> 90483 | AL23: =ROUND(('Income Statement Assumptions'!$B110*(1+'Income Statement Assumptions'!$D110)*(1+'Income Statement Assumptions'!$D110)*(1+'Income Statement Assumptions'!D110))*(1+'Income Statement Assumptions'!I110)*'Income Statement Assumptions'!N$58,0) -> 128084
A25: =A8 -> Product 3 | AA25: =SUM(O25:Z25) -> 0
A26: ='Income Statement Assumptions'!A113 -> repair labor | B26: ='Income Statement Assumptions'!$B113*'Income Statement Assumptions'!B70 -> 0 | C26: ='Income Statement Assumptions'!$B113*'Income Statement Assumptions'!C70 -> 0 | D26: ='Income Statement Assumptions'!$B113*'Income Statement Assumptions'!D70 -> 0 | E26: ='Income Statement Assumptions'!$B113*'Income Statement Assumptions'!E70 -> 0 | F26: ='Income Statement Assumptions'!$B113*'Income Statement Assumptions'!F70 -> 0 | G26: ='Income Statement Assumptions'!$B113*'Income Statement Assumptions'!G70 -> 0 | H26: ='Income Statement Assumptions'!$B113*'Income Statement Assumptions'!H70 -> 210 | I26: ='Income Statement Assumptions'!$B113*'Income Statement Assumptions'!I70 -> 215 | ... M26: ='Income Statement Assumptions'!$B113*'Income Statement Assumptions'!M70 -> 400 | N26: =SUM(B26:M26) -> 1795 | O26: =ROUND(('Income Statement Assumptions'!B$75*('Income Statement Assumptions'!$B113*(1+'Income Statement Assumptions'!$F$113))),0) -> 454 | P26: =ROUND(('Income Statement Assumptions'!C$75*('Income Statement Assumptions'!$B113*(1+'Income Statement Assumptions'!$F$113))),0) -> 510 | Q26: =ROUND(('Income Statement Assumptions'!D$75*('Income Statement Assumptions'!$B113*(1+'Income Statement Assumptions'!$F$113))),0) -> 574 | R26: =ROUND(('Income Statement Assumptions'!E$75*('Income Statement Assumptions'!$B113*(1+'Income Statement Assumptions'!$F$113))),0) -> 646 | S26: =ROUND(('Income Statement Assumptions'!F$75*('Income Statement Assumptions'!$B113*(1+'Income Statement Assumptions'!$F$113))),0) -> 727 | T26: =ROUND(('Income Statement Assumptions'!G$75*('Income Statement Assumptions'!$B113*(1+'Income Statement Assumptions'!$F$113))),0) -> 817 | U26: =ROUND(('Income Statement Assumptions'!H$75*('Income Statement Assumptions'!$B113*(1+'Income Statement Assumptions'!$F$113))),0) -> 920 | V26: =ROUND(('Income Statement Assumptions'!I$75*('Income Statement Assumptions'!$B113*(1+'Income Statement Assumptions'!$F$113))),0) -> 1035 | ... Z26: =ROUND(('Income Statement Assumptions'!M$75*('Income Statement Assumptions'!$B113*(1+'Income Statement Assumptions'!$F$113))),0) -> 1657 | AA26: =SUM(O26:Z26) -> 11286 | AB26: =ROUND(('Income Statement Assumptions'!$B113*(1+'Income Statement Assumptions'!$D113)*(1+'Income Statement Assumptions'!$G113))*'Income Statement Assumptions'!D$80,0) -> 6205 | AC26: =ROUND(('Income Statement Assumptions'!$B113*(1+'Income Statement Assumptions'!$D113)*(1+'Income Statement Assumptions'!$G113))*'Income Statement Assumptions'!G$80,0) -> 7756 | AD26: =ROUND(('Income Statement Assumptions'!$B113*(1+'Income Statement Assumptions'!$D113)*(1+'Income Statement Assumptions'!$G113))*'Income Statement Assumptions'!J$80,0) -> 9695 | AE26: =ROUND(('Income Statement Assumptions'!$B113*(1+'Income Statement Assumptions'!$D113)*(1+'Income Statement Assumptions'!$G113))*'Income Statement Assumptions'!M$80,0) -> 12119 | AF26: =SUM(AB26:AE26) -> 35775 | AG26: =ROUND(('Income Statement Assumptions'!$B113*(1+'Income Statement Assumptions'!$D113)*(1+'Income Statement Assumptions'!$D113)*(1+'Income Statement Assumptions'!$H113)*'Income Statement Assumptions'!D$85),0) -> 15330 | AH26: =ROUND(('Income Statement Assumptions'!$B113*(1+'Income Statement Assumptions'!$D113)*(1+'Income Statement Assumptions'!$D113)*(1+'Income Statement Assumptions'!$H113)*'Income Statement Assumptions'!G$85),0) -> 17630 | AI26: =ROUND(('Income Statement Assumptions'!$B113*(1+'Income Statement Assumptions'!$D113)*(1+'Income Statement Assumptions'!$D113)*(1+'Income Statement Assumptions'!$H113)*'Income Statement Assumptions'!J$85),0) -> 20275 | AJ26: =ROUND(('Income Statement Assumptions'!$B113*(1+'Income Statement Assumptions'!$D113)*(1+'Income Statement Assumptions'!$D113)*(1+'Income Statement Assumptions'!$H113)*'Income Statement Assumptions'!M$85),0) -> 23316 | AK26: =SUM(AG26:AJ26) -> 76551 | AL26: =ROUND(('Income Statement Assumptions'!$B113*(1+'Income Statement Assumptions'!$D113)*(1+'Income Statement Assumptions'!$D113)*(1+'Income Statement Assumptions'!D113))*(1+'Income Statement Assumptions'!I113)*'Income Statement Assumptions'!N$90,0) -> 117478
A27: ='Income Statement Assumptions'!A114 -> shipping | B27: ='Income Statement Assumptions'!$B114*'Income Statement Assumptions'!B70 -> 0 | C27: ='Income Statement Assumptions'!$B114*'Income Statement Assumptions'!C70 -> 0 | D27: ='Income Statement Assumptions'!$B114*'Income Statement Assumptions'!D70 -> 0 | E27: ='Income Statement Assumptions'!$B114*'Income Statement Assumptions'!E70 -> 0 | F27: ='Income Statement Assumptions'!$B114*'Income Statement Assumptions'!F70 -> 0 | G27: ='Income Statement Assumptions'!$B114*'Income Statement Assumptions'!G70 -> 0 | H27: ='Income Statement Assumptions'!$B114*'Income Statement Assumptions'!H70 -> 105 | I27: ='Income Statement Assumptions'!$B114*'Income Statement Assumptions'!I70 -> 107.5 | ... M27: ='Income Statement Assumptions'!$B114*'Income Statement Assumptions'!M70 -> 200 | N27: =SUM(B27:M27) -> 897.5 | O27: =ROUND(('Income Statement Assumptions'!B$75*('Income Statement Assumptions'!$B114*(1+'Income Statement Assumptions'!$F$113))),0) -> 227 | P27: =ROUND(('Income Statement Assumptions'!C$75*('Income Statement Assumptions'!$B114*(1+'Income Statement Assumptions'!$F$113))),0) -> 255 | Q27: =ROUND(('Income Statement Assumptions'!D$75*('Income Statement Assumptions'!$B114*(1+'Income Statement Assumptions'!$F$113))),0) -> 287 | R27: =ROUND(('Income Statement Assumptions'!E$75*('Income Statement Assumptions'!$B114*(1+'Income Statement Assumptions'!$F$113))),0) -> 323 | S27: =ROUND(('Income Statement Assumptions'!F$75*('Income Statement Assumptions'!$B114*(1+'Income Statement Assumptions'!$F$113))),0) -> 363 | T27: =ROUND(('Income Statement Assumptions'!G$75*('Income Statement Assumptions'!$B114*(1+'Income Statement Assumptions'!$F$113))),0) -> 409 | U27: =ROUND(('Income Statement Assumptions'!H$75*('Income Statement Assumptions'!$B114*(1+'Income Statement Assumptions'!$F$113))),0) -> 460 | V27: =ROUND(('Income Statement Assumptions'!I$75*('Income Statement Assumptions'!$B114*(1+'Income Statement Assumptions'!$F$113))),0) -> 517 | ... Z27: =ROUND(('Income Statement Assumptions'!M$75*('Income Statement Assumptions'!$B114*(1+'Income Statement Assumptions'!$F$113))),0) -> 829 | AA27: =SUM(O27:Z27) -> 5643 | AB27: =ROUND(('Income Statement Assumptions'!$B114*(1+'Income Statement Assumptions'!$D114)*(1+'Income Statement Assumptions'!$G114))*'Income Statement Assumptions'!D$80,0) -> 2925 | AC27: =ROUND(('Income Statement Assumptions'!$B114*(1+'Income Statement Assumptions'!$D114)*(1+'Income Statement Assumptions'!$G114))*'Income Statement Assumptions'!G$80,0) -> 3657 | AD27: =ROUND(('Income Statement Assumptions'!$B114*(1+'Income Statement Assumptions'!$D114)*(1+'Income Statement Assumptions'!$G114))*'Income Statement Assumptions'!J$80,0) -> 4571 | AE27: =ROUND(('Income Statement Assumptions'!$B114*(1+'Income Statement Assumptions'!$D114)*(1+'Income Statement Assumptions'!$G114))*'Income Statement Assumptions'!M$80,0) -> 5714 | AF27: =SUM(AB27:AE27) -> 16867 | AG27: =ROUND(('Income Statement Assumptions'!$B114*(1+'Income Statement Assumptions'!$D114)*(1+'Income Statement Assumptions'!$D114)*(1+'Income Statement Assumptions'!$H114)*'Income Statement Assumptions'!D$85),0) -> 6899 | AH27: =ROUND(('Income Statement Assumptions'!$B114*(1+'Income Statement Assumptions'!$D114)*(1+'Income Statement Assumptions'!$D114)*(1+'Income Statement Assumptions'!$H114)*'Income Statement Assumptions'!G$85),0) -> 7934 | AI27: =ROUND(('Income Statement Assumptions'!$B114*(1+'Income Statement Assumptions'!$D114)*(1+'Income Statement Assumptions'!$D114)*(1+'Income Statement Assumptions'!$H114)*'Income Statement Assumptions'!J$85),0) -> 9124 | AJ27: =ROUND(('Income Statement Assumptions'!$B114*(1+'Income Statement Assumptions'!$D114)*(1+'Income Statement Assumptions'!$D114)*(1+'Income Statement Assumptions'!$H114)*'Income Statement Assumptions'!M$85),0) -> 10493 | AK27: =SUM(AG27:AJ27) -> 34450 | AL27: =ROUND(('Income Statement Assumptions'!$B114*(1+'Income Statement Assumptions'!$D114)*(1+'Income Statement Assumptions'!$D114)*(1+'Income Statement Assumptions'!D114))*(1+'Income Statement Assumptions'!I114)*'Income Statement Assumptions'!N$90,0) -> 48765
